Workbook
Name __________fck1: #REF!
Name __________fck1: #REF!
Name __________fck1: #REF!
Name __________fck2: #REF!
Name __________fck2: #REF!
Name __________fck2: #REF!
Name __________le2: #REF!
Name __________le2: #REF!
Name __________le2: #REF!
Name __________lx5: #REF!
Name __________lx5: #REF!
Name __________lx5: #REF!
Name __________ly6: #REF!
Name __________ly6: #REF!
Name __________ly6: #REF!
Name __________Pb2: #REF!
Name __________Pb2: #REF!
Name __________Pb2: #REF!
Name _______fck1: #REF!
Name _______fck1: #REF!
Name _______fck1: #REF!
Name _______fck2: #REF!
Name _______fck2: #REF!
Name _______fck2: #REF!
Name _______le2: #REF!
Name _______le2: #REF!
Name _______le2: #REF!
Name _______lx5: #REF!
Name _______lx5: #REF!
Name _______lx5: #REF!
Name _______ly6: #REF!
Name _______ly6: #REF!
Name _______ly6: #REF!
Name _______Pb2: #REF!
Name _______Pb2: #REF!
Name _______Pb2: #REF!
Name _____fck1: #REF!
Name _____fck1: #REF!
Name _____fck1: #REF!
Name _____fck2: #REF!
Name _____fck2: #REF!
Name _____fck2: #REF!
Name _____le2: #REF!
Name _____le2: #REF!
Name _____le2: #REF!
Name _____lx5: #REF!
Name _____lx5: #REF!
Name _____lx5: #REF!
Name _____ly6: #REF!
Name _____ly6: #REF!
Name _____ly6: #REF!
Name _____Pb2: #REF!
Name _____Pb2: #REF!
Name _____Pb2: #REF!
Name _____TB2: #REF!
Name _____TB2: #REF!
Name _____TB2: #REF!
Name ___fck1: #REF!
Name ___fck1: #REF!
Name ___fck1: #REF!

Sheet CP
Y1: Entry | Z1: Auto | AA1: Auto | AB1: Item
B8: ROUTINE VERTICAL
B9: PILE LOAD TEST
B11: Name of the work:
B12: =Y6 -> 0 | Y12: "Upgradation of District Hospital
B13: =IF(Y13="","",Y13) -> Construction of Super Speciality Hospital block | Y13: Construction of Super Speciality Hospital block
B14: =IF(Y14="","",Y14) -> And allied buildings with at Tezpur Medical | Y14: And allied buildings with at Tezpur Medical
B15: =IF(Y15="","",Y15) -> College, Jorhat Medical Diphu Medical College | Y15: College, Jorhat Medical Diphu Medical College
B16: =IF(Y16="","",Y16) -> campus including civil, MEP works External | Y16: campus including civil, MEP works External
B17: =IF(Y17="","",Y17) -> Development works. Package No- 1-1B | Y17: Development works. Package No- 1-1B
B19: Location:
B20: =IF(Y20="","",Y20) -> Tezpur Super Speciality Hospital, TMCH | Y20: Tezpur Super Speciality Hospital, TMCH
B22: EMPLOYER:
B23: AHIDMS
B24: Nayantara super market complex, Guwahati
B26: ENGINEER
B27: Executive Engineer, PWD
B28: Sonitpur, Dist. Territorial Building division, tezpur
B30: PMC:
B31: =IF(Y31="","",Y31) -> RITES LTD-MUKESH & ASSOCIATES- (JV) | Y31: RITES LTD-MUKESH & ASSOCIATES- (JV)
B32: Nayantara super market complex, Guwahati
B34: CONTRACTOR:
B35: =IF(Y35="","",Y35) -> NCC Limited | Y35: NCC Limited
B36: Eastern regional office, Kolkata
L38: PREPARED BY :
L39: NABL ACCREDITED LABORATORY (ISO/IEC 17025:2017 Certificate No: TC-17241)
L40: Northeast Research Laboratory & Testing Private Limited
F43: Office: Room No.50, G.M.C. Market Complex, Chandmari, Guwahati-781003
E44: Laboratory: House No 4, Salbari- Noonmati Road, Noonmati, Guwahati, Assam 781020
E49: Report/ Certificate No.: | I49: NERLT120626N1 | N49: Date of report issue: | R49: 46185

Sheet C&I
C2: NORTHEAST RESEARCH LABORATORY &
C3: TESTING PRIVATE LIMITED
B5: M/N : (+91) 9577782943, EMAIL : OFFICE@NERLT.COM
B6: Office: Room No.50, G.M.C. Market Complex, Chandmari, Guwahati-781003
B7: Lab: House No 4, Salbari- Noonmati Road, Noonmati, Guwahati, Assam 781020
B10: CONTENTS
B12: Sl. No | C12: Description | AD12: Page No.
B13: 1.01 | C13: INTRODUCTION | AD13: 3
B14: 1.02 | C14: OBJECTIVE | AD14: 3
B15: 1.03 | C15: TESTING EQUIPMENTS | AD15: 3
B16: 1.04 | C16: TEST PROCEDURE | AD16: 3
B17: 2.01 | C17: TABLE 1 : BASIC DATA | AD17: 3
B18: 2.02 | C18: INTERPRETATION | AD18: 3
B19: 2.03 | C19: =UPPER("table 2 a : dial gause reading corresponding to Loading") -> TABLE 2 A : DIAL GAUSE READING CORRESPONDING TO LOADING | AD19: 4-6
B20: 2.04 | C20: =UPPER("table 2 B : dial gause reading corresponding to Unloading") -> TABLE 2 B : DIAL GAUSE READING CORRESPONDING TO UNLOADING | AD20: 7
B21: 2.05 | C21: =UPPER("Fig 1 : load settlement graph from field data") -> FIG 1 : LOAD SETTLEMENT GRAPH FROM FIELD DATA | AD21: 8
B22: 2.06 | C22: ANALYSIS OF TEST RESULTS | AD22: 8
B23: 3 | C23: SITE PHOTO GRAPHS | AD23: 9

Sheet Th1
AL1: Entry | AM1: Auto | AN1: Auto | AO1: Item
C2: NORTHEAST RESEARCH LABORATORY &
C3: TESTING PRIVATE LIMITED
B5: M/N : (+91) 9577782943, EMAIL : OFFICE@NERLT.COM
B6: Office: Room No.50, G.M.C. Market Complex, Chandmari, Guwahati-781003
B7: Lab: House No 4, Salbari- Noonmati Road, Noonmati, Guwahati, Assam 781020
B11: 1.01 INTRODUCTION:
B13: =CONCATENATE("Routine Vertical Pile load test was conducted on behalf of ''",TEXT(AN13,"Bold"),"'' for ''", AN14,"''.") -> Routine Vertical Pile load test was conducted on behalf of ''NCC Limited'' for ''Construction of Super Speciality Hospital block And allied buildings with at Tezpur Medical College, Jorhat Medical Diphu Medical College campus including civil, MEP works External Development works. Package No- 1-1B''. | AL13: CONTRACTOR: | AN13: NCC Limited
AL14: Name of the work: | AN14: Construction of Super Speciality Hospital block And allied buildings with at Tezpur Medical College, Jorhat Medical Diphu Medical College campus including civil, MEP works External Development works. Package No- 1-1B
B16: 1.02 OBJECTIVE:
B18: The main objective of the test was to check the estimated safe load and extent of safety for the specific functional requirement of the pile at the working load and also detection of any unusual performance contrary to the findings of the initial test.
B23: 1.03 TESTING EQUIPMENTS:
B25: Pressure gauge, Dial gauge with magnetic stand, Hydraulic Jack, Oil Pump fitted with Hose Pipe, Adopter for fixing pressure gauge, Kentledge-sand bags on ISMB Girder welded with plates on top.
B28: 1.04 TEST PROCEDURE:
B30: =CONCATENATE("Vertical load test (compression) was done as per IS 2911 (PART -IV) 2013 in which compression load was applied"," to the pile top (after preparation of the pile top) by means of a hydraulic jack against rolled steel joist capable of providing reaction and the settlement was recorded by ",AL30," dial gauges of 0.01 mm sensitivity, each positioned at equal distance around the pile and ","held by datum bars resting on immovable supports at minimum distance of 3D from the edge of the pile, Where D is the pile stem diameter of circular pile.") -> Vertical load test (compression) was done as per IS 2911 (PART -IV) 2013 in which compression load was applied to the pile top (after preparation of the pile top) by means of a hydraulic jack against rolled steel joist capable of providing reaction and the settlement was recorded by four dial gauges of 0.01 mm sensitivity, each positioned at equal distance around the pile and held by datum bars resting on immovable supports at minimum distance of 3D from the edge of the pile, Where D is the pile stem diameter of circular pile. | AL30: four
B31: The reaction for the jack was obtained from a kentledge placed on a plateform supported clear of the test pile. The center of gravity of the kentledge was tried to be kept on the axis of the pile and the load applied by the jack was also made co-axial with this pile.
B32: =CONCATENATE("The test was carried out by applying a series of vertical downward incremental each load of ",TEXT(AL32,"0.00")," Tons.") -> The test was carried out by applying a series of vertical downward incremental each load of 40.00 Tons. | AL32: 40
B35: 2.01 : TABLE 1 : BASIC DATA:
B36: Sl No | D36: PARTICULARS | O36: VALUES / DETAILS
B37: 1 | D37: Pile No. | O37: =CONCATENATE(AL37) -> 240 | AL37: 240
B38: 2 | D38: Diameter of pile | O38: =CONCATENATE(AL38, " mm") -> 750 mm | AL38: 750
B39: 3 | D39: Date of Casting | O39: =TEXT(AL39,"DD-MM-YYYY") -> 17-02-2026 | AL39: 46070
B40: 4 | D40: Date of Test | O40: =TEXT(AL40,"DD-MM-YYYY") -> 20-05-2026 | AL40: 46162
B41: 5 | D41: Type of Test | O41: =CONCATENATE(AL41) -> Routine Vertical Pile Load Test. | AL41: Routine Vertical Pile Load Test.
B42: 6 | D42: Type of Pile | O42: Cast in Situ pile | AL42: Cast in Situ pile
B43: 7 | D43: Length of Pile | O43: =CONCATENATE(AL43, " m") -> 20 m | AL43: 20
B44: 8 | D44: Estimated safe load | O44: =CONCATENATE(AL44, " Tonne") -> 200 Tonne | AL44: 200
B45: 9 | D45: Test Load | O45: =CONCATENATE(AL45, " Tonne") -> 300 Tonne | AL45: 300
B46: 10 | D46: Material of Pile | O46: =CONCATENATE(AL46) -> R.C.C. | AL46: R.C.C.
B48: 2.02 INTERPRETATION :
B50: As per IS 2911 (Part 4) : 2013 Clause No 7.1.5.1:
B51: Routine test shall be carried for a test load of at least 1.5 times the working load. 1) The Maximum settlement at the test load being not greater than 12 mm for piles diameter up to and including 600 mm and 2) The Maximum settlement at the test load being not greater than 18 mm or 2 percent of pile diameter whichever is less for piles of diameter more than 600 mm.

Sheet T1L
A3: NORTHEAST RESEARCH LABORATORY &
A4: TESTING PRIVATE LIMITED
A6: M/N : (+91) 9577782943, EMAIL : OFFICE@NERLT.COM
A7: Office: Room No.50, G.M.C. Market Complex, Chandmari, Guwahati-781003
A8: Lab: House No 4, Salbari- Noonmati Road, Noonmati, Guwahati, Assam 781020
A11: =UPPER("2.03 : table 2 A : dial gause reading corresponding to Loading") -> 2.03 : TABLE 2 A : DIAL GAUSE READING CORRESPONDING TO LOADING | M11: X1 | N11: Y1
A12: DATE | B12: TIME | C12: LOAD APPLIED | D12: DIAL GAUGE READING | H12: MEAN | J12: Select Load for Highest mean | K12: Selected Mean | L12: Load Nos | M12: Loading Mean | N12: Load value in Tonne
D13: (mm)
B14: (HOURS) | C14: (TONNE) | D14: DG-1 | E14: DG-2 | F14: DG-3 | G14: DG-4 | H14: (mm)
A15: LOADING
A16: 46162 | B16: 12.666667 | C16: 0 | D16: 0 | E16: 0 | F16: 0 | G16: 0 | H16: =IFERROR(AVERAGE(D16:G16),"") -> 0 | J16: L1 | K16: =IF(J16="","",ROUND(H16,2)) -> 0 | L16: L1 | M16: =IFERROR(VLOOKUP(L16,$J$16:$K$406,2,FALSE),"") -> 0 | N16: =IFERROR(SMALL($C$16:$C$406,O16),"") -> 0 | O16: 1
A17: =A16 -> 46162 | B17: =IF(C17<>"",B16, B16 + TIME(0, 15, 0)) -> 12.666667 | C17: 40 | D17: 0.41 | E17: 0.37 | F17: 0.4 | G17: 0.34 | H17: =IFERROR(AVERAGE(D17:G17),"") -> 0.38 | K17: =IF(J17="","",ROUND(H17,2)) | L17: L2 | M17: =IFERROR(VLOOKUP(L17,$J$16:$K$406,2,FALSE),"") -> 0.47 | N17: =IFERROR(SMALL($C$16:$C$406,O17),"") -> 40 | O17: 2
A18: =A17 -> 46162 | B18: =IF(C18<>"",B17, B17 + TIME(0, 15, 0)) -> 12.677083 | D18: 0.43 | E18: 0.41 | F18: 0.42 | G18: 0.37 | H18: =IFERROR(AVERAGE(D18:G18),"") -> 0.4075 | K18: =IF(J18="","",ROUND(H18,2)) | L18: L3 | M18: =IFERROR(VLOOKUP(L18,$J$16:$K$406,2,FALSE),"") -> 0.95 | N18: =IFERROR(SMALL($C$16:$C$406,O18),"") -> 80 | O18: 3
A19: =A18 -> 46162 | B19: =IF(C19<>"",B18, B18 + TIME(0, 15, 0)) -> 12.6875 | D19: 0.45 | E19: 0.42 | F19: 0.44 | G19: 0.39 | H19: =IFERROR(AVERAGE(D19:G19),"") -> 0.425 | K19: =IF(J19="","",ROUND(H19,2)) | L19: L4 | M19: =IFERROR(VLOOKUP(L19,$J$16:$K$406,2,FALSE),"") -> 1.37 | N19: =IFERROR(SMALL($C$16:$C$406,O19),"") -> 120 | O19: 4
A20: =A19 -> 46162 | B20: =IF(C20<>"",B19, B19 + TIME(0, 15, 0)) -> 12.697917 | D20: 0.47 | E20: 0.44 | F20: 0.47 | G20: 0.41 | H20: =IFERROR(AVERAGE(D20:G20),"") -> 0.4475 | K20: =IF(J20="","",ROUND(H20,2)) | L20: L5 | M20: =IFERROR(VLOOKUP(L20,$J$16:$K$406,2,FALSE),"") -> 1.84 | N20: =IFERROR(SMALL($C$16:$C$406,O20),"") -> 160 | O20: 5
A21: =A20 -> 46162 | B21: =IF(C21<>"",B20, B20 + TIME(0, 15, 0)) -> 12.708333 | D21: 0.49 | E21: 0.46 | F21: 0.48 | G21: 0.43 | H21: =IFERROR(AVERAGE(D21:G21),"") -> 0.465 | J21: L2 | K21: =IF(J21="","",ROUND(H21,2)) -> 0.47 | L21: L6 | M21: =IFERROR(VLOOKUP(L21,$J$16:$K$406,2,FALSE),"") -> 2.2 | N21: =IFERROR(SMALL($C$16:$C$406,O21),"") -> 200 | O21: 6
A22: =A21 -> 46162 | B22: =IF(C22<>"",B21, B21 + TIME(0, 15, 0)) -> 12.708333 | C22: 80 | D22: 0.91 | E22: 0.79 | F22: 0.87 | G22: 0.84 | H22: =IFERROR(AVERAGE(D22:G22),"") -> 0.8525 | K22: =IF(J22="","",ROUND(H22,2)) | L22: L7 | M22: =IFERROR(VLOOKUP(L22,$J$16:$K$406,2,FALSE),"") -> 2.93 | N22: =IFERROR(SMALL($C$16:$C$406,O22),"") -> 240 | O22: 7
A23: =A22 -> 46162 | B23: =IF(C23<>"",B22, B22 + TIME(0, 15, 0)) -> 12.71875 | D23: 0.93 | E23: 0.82 | F23: 0.89 | G23: 0.86 | H23: =IFERROR(AVERAGE(D23:G23),"") -> 0.875 | K23: =IF(J23="","",ROUND(H23,2)) | L23: L8 | M23: =IFERROR(VLOOKUP(L23,$J$16:$K$406,2,FALSE),"") -> 3.43 | N23: =IFERROR(SMALL($C$16:$C$406,O23),"") -> 280 | O23: 8
A24: =A23 -> 46162 | B24: =IF(C24<>"",B23, B23 + TIME(0, 15, 0)) -> 12.729167 | D24: 0.96 | E24: 0.84 | F24: 0.93 | G24: 0.88 | H24: =IFERROR(AVERAGE(D24:G24),"") -> 0.9025 | K24: =IF(J24="","",ROUND(H24,2)) | L24: L9 | M24: =IFERROR(VLOOKUP(L24,$J$16:$K$406,2,FALSE),"") -> 4.18 | N24: =IFERROR(SMALL($C$16:$C$406,O24),"") -> 300 | O24: 9
A25: =A24 -> 46162 | B25: =IF(C25<>"",B24, B24 + TIME(0, 15, 0)) -> 12.739583 | D25: 0.97 | E25: 0.87 | F25: 0.96 | G25: 0.9 | H25: =IFERROR(AVERAGE(D25:G25),"") -> 0.925 | K25: =IF(J25="","",ROUND(H25,2)) | L25: L10 | M25: =IFERROR(VLOOKUP(L25,$J$16:$K$406,2,FALSE),"") | N25: =IFERROR(SMALL($C$16:$C$406,O25),"") | O25: 10
A26: =A25 -> 46162 | B26: =IF(C26<>"",B25, B25 + TIME(0, 15, 0)) -> 12.75 | D26: 0.99 | E26: 0.89 | F26: 0.98 | G26: 0.92 | H26: =IFERROR(AVERAGE(D26:G26),"") -> 0.945 | J26: L3 | K26: =IF(J26="","",ROUND(H26,2)) -> 0.95 | L26: L11 | M26: =IFERROR(VLOOKUP(L26,$J$16:$K$406,2,FALSE),"") | N26: =IFERROR(SMALL($C$16:$C$406,O26),"") | O26: 11
A27: =A26 -> 46162 | B27: =IF(C27<>"",B26, B26 + TIME(0, 15, 0)) -> 12.75 | C27: 120 | D27: 1.36 | E27: 1.22 | F27: 1.28 | G27: 1.25 | H27: =IFERROR(AVERAGE(D27:G27),"") -> 1.2775 | K27: =IF(J27="","",ROUND(H27,2)) | L27: L12 | M27: =IFERROR(VLOOKUP(L27,$J$16:$K$406,2,FALSE),"") | N27: =IFERROR(SMALL($C$16:$C$406,O27),"") | O27: 12
A28: =A27 -> 46162 | B28: =IF(C28<>"",B27, B27 + TIME(0, 15, 0)) -> 12.760417 | D28: 1.38 | E28: 1.25 | F28: 1.3 | G28: 1.27 | H28: =IFERROR(AVERAGE(D28:G28),"") -> 1.3 | K28: =IF(J28="","",ROUND(H28,2)) | L28: L13 | M28: =IFERROR(VLOOKUP(L28,$J$16:$K$406,2,FALSE),"") | N28: =IFERROR(SMALL($C$16:$C$406,O28),"") | O28: 13
A29: =A28 -> 46162 | B29: =IF(C29<>"",B28, B28 + TIME(0, 15, 0)) -> 12.770833 | D29: 1.4 | E29: 1.27 | F29: 1.33 | G29: 1.3 | H29: =IFERROR(AVERAGE(D29:G29),"") -> 1.325 | K29: =IF(J29="","",ROUND(H29,2)) | L29: L14 | M29: =IFERROR(VLOOKUP(L29,$J$16:$K$406,2,FALSE),"") | N29: =IFERROR(SMALL($C$16:$C$406,O29),"") | O29: 14
A30: =A29 -> 46162 | B30: =IF(C30<>"",B29, B29 + TIME(0, 15, 0)) -> 12.78125 | D30: 1.43 | E30: 1.3 | F30: 1.35 | G30: 1.32 | H30: =IFERROR(AVERAGE(D30:G30),"") -> 1.35 | K30: =IF(J30="","",ROUND(H30,2)) | L30: L15 | M30: =IFERROR(VLOOKUP(L30,$J$16:$K$406,2,FALSE),"") | N30: =IFERROR(SMALL($C$16:$C$406,O30),"") | O30: 15
A31: =A30 -> 46162 | B31: =IF(C31<>"",B30, B30 + TIME(0, 15, 0)) -> 12.791667 | D31: 1.46 | E31: 1.32 | F31: 1.37 | G31: 1.34 | H31: =IFERROR(AVERAGE(D31:G31),"") -> 1.3725 | J31: L4 | K31: =IF(J31="","",ROUND(H31,2)) -> 1.37 | L31: L16 | M31: =IFERROR(VLOOKUP(L31,$J$16:$K$406,2,FALSE),"") | N31: =IFERROR(SMALL($C$16:$C$406,O31),"") | O31: 16
A32: =A31 -> 46162 | B32: =IF(C32<>"",B31, B31 + TIME(0, 15, 0)) -> 12.791667 | C32: 160 | D32: 1.79 | E32: 1.68 | F32: 1.72 | G32: 1.8 | H32: =IFERROR(AVERAGE(D32:G32),"") -> 1.7475 | K32: =IF(J32="","",ROUND(H32,2)) | L32: L17 | M32: =IFERROR(VLOOKUP(L32,$J$16:$K$406,2,FALSE),"") | N32: =IFERROR(SMALL($C$16:$C$406,O32),"") | O32: 17
A33: =A32 -> 46162 | B33: =IF(C33<>"",B32, B32 + TIME(0, 15, 0)) -> 12.802083 | D33: 1.82 | E33: 1.7 | F33: 1.75 | G33: 1.83 | H33: =IFERROR(AVERAGE(D33:G33),"") -> 1.775 | K33: =IF(J33="","",ROUND(H33,2)) | L33: L18 | M33: =IFERROR(VLOOKUP(L33,$J$16:$K$406,2,FALSE),"") | N33: =IFERROR(SMALL($C$16:$C$406,O33),"") | O33: 18
A34: =A33 -> 46162 | B34: =IF(C34<>"",B33, B33 + TIME(0, 15, 0)) -> 12.8125 | D34: 1.85 | E34: 1.73 | F34: 1.78 | G34: 1.85 | H34: =IFERROR(AVERAGE(D34:G34),"") -> 1.8025 | K34: =IF(J34="","",ROUND(H34,2)) | L34: L19 | M34: =IFERROR(VLOOKUP(L34,$J$16:$K$406,2,FALSE),"") | N34: =IFERROR(SMALL($C$16:$C$406,O34),"") | O34: 19
A35: =A34 -> 46162 | B35: =IF(C35<>"",B34, B34 + TIME(0, 15, 0)) -> 12.822917 | D35: 1.87 | E35: 1.75 | F35: 1.8 | G35: 1.87 | H35: =IFERROR(AVERAGE(D35:G35),"") -> 1.8225 | K35: =IF(J35="","",ROUND(H35,2)) | L35: L20 | M35: =IFERROR(VLOOKUP(L35,$J$16:$K$406,2,FALSE),"") | N35: =IFERROR(SMALL($C$16:$C$406,O35),"") | O35: 20
A36: =A35 -> 46162 | B36: =IF(C36<>"",B35, B35 + TIME(0, 15, 0)) -> 12.833333 | D36: 1.89 | E36: 1.77 | F36: 1.82 | G36: 1.89 | H36: =IFERROR(AVERAGE(D36:G36),"") -> 1.8425 | J36: L5 | K36: =IF(J36="","",ROUND(H36,2)) -> 1.84 | L36: L21 | M36: =IFERROR(VLOOKUP(L36,$J$16:$K$406,2,FALSE),"") | N36: =IFERROR(SMALL($C$16:$C$406,O36),"") | O36: 21
A37: =A36 -> 46162 | B37: =IF(C37<>"",B36, B36 + TIME(0, 15, 0)) -> 12.833333 | C37: 200 | D37: 2.13 | E37: 1.99 | F37: 2.12 | G37: 2.11 | H37: =IFERROR(AVERAGE(D37:G37),"") -> 2.0875 | K37: =IF(J37="","",ROUND(H37,2)) | L37: L22 | M37: =IFERROR(VLOOKUP(L37,$J$16:$K$406,2,FALSE),"") | N37: =IFERROR(SMALL($C$16:$C$406,O37),"") | O37: 22
A38: =A37 -> 46162 | B38: =IF(C38<>"",B37, B37 + TIME(0, 15, 0)) -> 12.84375 | D38: 2.15 | E38: 2.02 | F38: 2.13 | G38: 2.15 | H38: =IFERROR(AVERAGE(D38:G38),"") -> 2.1125 | K38: =IF(J38="","",ROUND(H38,2)) | L38: L23 | M38: =IFERROR(VLOOKUP(L38,$J$16:$K$406,2,FALSE),"") | N38: =IFERROR(SMALL($C$16:$C$406,O38),"") | O38: 23
A39: =A38 -> 46162 | B39: =IF(C39<>"",B38, B38 + TIME(0, 15, 0)) -> 12.854167 | D39: 2.18 | E39: 2.05 | F39: 2.15 | G39: 2.18 | H39: =IFERROR(AVERAGE(D39:G39),"") -> 2.14 | K39: =IF(J39="","",ROUND(H39,2)) | L39: L24 | M39: =IFERROR(VLOOKUP(L39,$J$16:$K$406,2,FALSE),"") | N39: =IFERROR(SMALL($C$16:$C$406,O39),"") | O39: 24
A40: =A39 -> 46162 | B40: =IF(C40<>"",B39, B39 + TIME(0, 15, 0)) -> 12.864583 | D40: 2.21 | E40: 2.07 | F40: 2.18 | G40: 2.21 | H40: =IFERROR(AVERAGE(D40:G40),"") -> 2.1675 | K40: =IF(J40="","",ROUND(H40,2)) | L40: L25 | M40: =IFERROR(VLOOKUP(L40,$J$16:$K$406,2,FALSE),"") | N40: =IFERROR(SMALL($C$16:$C$406,O40),"") | O40: 25
A41: =A40 -> 46162 | B41: =IF(C41<>"",B40, B40 + TIME(0, 15, 0)) -> 12.875 | D41: 2.23 | E41: 2.11 | F41: 2.21 | G41: 2.23 | H41: =IFERROR(AVERAGE(D41:G41),"") -> 2.195 | J41: L6 | K41: =IF(J41="","",ROUND(H41,2)) -> 2.2 | L41: L26 | M41: =IFERROR(VLOOKUP(L41,$J$16:$K$406,2,FALSE),"") | N41: =IFERROR(SMALL($C$16:$C$406,O41),"") | O41: 26
A42: =A41 -> 46162 | B42: =IF(C42<>"",B41, B41 + TIME(0, 15, 0)) -> 12.875 | C42: 240 | D42: 2.79 | E42: 2.81 | F42: 2.858 | G42: 2.83 | H42: =IFERROR(AVERAGE(D42:G42),"") -> 2.822 | K42: =IF(J42="","",ROUND(H42,2)) | L42: L27 | M42: =IFERROR(VLOOKUP(L42,$J$16:$K$406,2,FALSE),"") | N42: =IFERROR(SMALL($C$16:$C$406,O42),"") | O42: 27
A43: =A42 -> 46162 | B43: =IF(C43<>"",B42, B42 + TIME(0, 15, 0)) -> 12.885417 | D43: 2.81 | E43: 2.84 | F43: 2.87 | G43: 2.86 | H43: =IFERROR(AVERAGE(D43:G43),"") -> 2.845 | K43: =IF(J43="","",ROUND(H43,2)) | L43: L28 | M43: =IFERROR(VLOOKUP(L43,$J$16:$K$406,2,FALSE),"") | N43: =IFERROR(SMALL($C$16:$C$406,O43),"") | O43: 28
A44: =A43 -> 46162 | B44: =IF(C44<>"",B43, B43 + TIME(0, 15, 0)) -> 12.895833 | D44: 2.84 | E44: 2.87 | F44: 2.89 | G44: 2.88 | H44: =IFERROR(AVERAGE(D44:G44),"") -> 2.87 | K44: =IF(J44="","",ROUND(H44,2)) | L44: L29 | M44: =IFERROR(VLOOKUP(L44,$J$16:$K$406,2,FALSE),"") | N44: =IFERROR(SMALL($C$16:$C$406,O44),"") | O44: 29
A45: =A44 -> 46162 | B45: =IF(C45<>"",B44, B44 + TIME(0, 15, 0)) -> 12.90625 | D45: 2.88 | E45: 2.89 | F45: 2.92 | G45: 2.92 | H45: =IFERROR(AVERAGE(D45:G45),"") -> 2.9025 | K45: =IF(J45="","",ROUND(H45,2)) | L45: L30 | M45: =IFERROR(VLOOKUP(L45,$J$16:$K$406,2,FALSE),"") | N45: =IFERROR(SMALL($C$16:$C$406,O45),"") | O45: 30
...

Sheet T1U
A3: NORTHEAST RESEARCH LABORATORY &
A4: TESTING PRIVATE LIMITED
A6: M/N : (+91) 9577782943, EMAIL : OFFICE@NERLT.COM
A7: Office: Room No.50, G.M.C. Market Complex, Chandmari, Guwahati-781003
A8: Lab: House No 4, Salbari- Noonmati Road, Noonmati, Guwahati, Assam 781020
A11: =UPPER("2.04 : table 2 B : dial gause reading corresponding to Unloading") -> 2.04 : TABLE 2 B : DIAL GAUSE READING CORRESPONDING TO UNLOADING | M11: X2 | N11: Y2
A12: DATE | B12: TIME | C12: LOAD APPLIED | D12: DIAL GAUGE READING | H12: MEAN | J12: Select Load for Highest mean | K12: Selected Mean | L12: uNLoad Nos | M12: Loading Mean | N12: Load value in Tonne
D13: (mm)
B14: (HOURS) | C14: (TONNE) | D14: DG-1 | E14: DG-2 | F14: DG-3 | G14: DG-4 | H14: (mm)
A15: UNLOADING
A16: 46164 | B16: 0 | C16: 300 | D16: 4.15 | E16: 4.2 | F16: 4.15 | G16: 4.22 | H16: =IFERROR(AVERAGE(D16:G16),"") -> 4.18 | J16: U9 | K16: =IF(J16="","",ROUND(H16,2)) -> 4.18 | L16: U1 | M16: =IFERROR(VLOOKUP(L16,$J$16:$K$405,2,FALSE),"") -> 3.04 | N16: =IFERROR(SMALL($C$16:$C$405,O16),"") -> 0 | O16: 1
A17: =A16 -> 46164 | B17: =IF(C17<>"", B16 + TIME(0, 30, 0),B16) -> 0.020833333 | C17: 280 | D17: 4.04 | E17: 4.1 | F17: 4.02 | G17: 4.14 | H17: =IFERROR(AVERAGE(D17:G17),"") -> 4.075 | J17: U8 | K17: =IF(J17="","",ROUND(H17,2)) -> 4.08 | L17: U2 | M17: =IFERROR(VLOOKUP(L17,$J$16:$K$405,2,FALSE),"") -> 3.13 | N17: =IFERROR(SMALL($C$16:$C$405,O17),"") -> 40 | O17: 2
A18: =A17 -> 46164 | B18: =IF(C18<>"", B17 + TIME(0, 30, 0),B17) -> 0.041666667 | C18: 240 | D18: 3.93 | E18: 3.98 | F18: 3.9 | G18: 3.97 | H18: =IFERROR(AVERAGE(D18:G18),"") -> 3.945 | J18: U7 | K18: =IF(J18="","",ROUND(H18,2)) -> 3.95 | L18: U3 | M18: =IFERROR(VLOOKUP(L18,$J$16:$K$405,2,FALSE),"") -> 3.23 | N18: =IFERROR(SMALL($C$16:$C$405,O18),"") -> 80 | O18: 3
A19: =A18 -> 46164 | B19: =IF(C19<>"", B18 + TIME(0, 30, 0),B18) -> 0.0625 | C19: 200 | D19: 3.82 | E19: 3.77 | F19: 3.77 | G19: 3.7 | H19: =IFERROR(AVERAGE(D19:G19),"") -> 3.765 | J19: U6 | K19: =IF(J19="","",ROUND(H19,2)) -> 3.77 | L19: U4 | M19: =IFERROR(VLOOKUP(L19,$J$16:$K$405,2,FALSE),"") -> 3.4 | N19: =IFERROR(SMALL($C$16:$C$405,O19),"") -> 120 | O19: 4
A20: =A19 -> 46164 | B20: =IF(C20<>"", B19 + TIME(0, 30, 0),B19) -> 0.083333333 | C20: 160 | D20: 3.7 | E20: 3.54 | F20: 3.52 | G20: 3.55 | H20: =IFERROR(AVERAGE(D20:G20),"") -> 3.5775 | J20: U5 | K20: =IF(J20="","",ROUND(H20,2)) -> 3.58 | L20: U5 | M20: =IFERROR(VLOOKUP(L20,$J$16:$K$405,2,FALSE),"") -> 3.58 | N20: =IFERROR(SMALL($C$16:$C$405,O20),"") -> 160 | O20: 5
A21: =A20 -> 46164 | B21: =IF(C21<>"", B20 + TIME(0, 30, 0),B20) -> 0.10416667 | C21: 120 | D21: 3.51 | E21: 3.36 | F21: 3.36 | G21: 3.38 | H21: =IFERROR(AVERAGE(D21:G21),"") -> 3.4025 | J21: U4 | K21: =IF(J21="","",ROUND(H21,2)) -> 3.4 | L21: U6 | M21: =IFERROR(VLOOKUP(L21,$J$16:$K$405,2,FALSE),"") -> 3.77 | N21: =IFERROR(SMALL($C$16:$C$405,O21),"") -> 200 | O21: 6
A22: =A21 -> 46164 | B22: =IF(C22<>"", B21 + TIME(0, 30, 0),B21) -> 0.125 | C22: 80 | D22: 3.27 | E22: 3.28 | F22: 3.21 | G22: 3.17 | H22: =IFERROR(AVERAGE(D22:G22),"") -> 3.2325 | J22: U3 | K22: =IF(J22="","",ROUND(H22,2)) -> 3.23 | L22: U7 | M22: =IFERROR(VLOOKUP(L22,$J$16:$K$405,2,FALSE),"") -> 3.95 | N22: =IFERROR(SMALL($C$16:$C$405,O22),"") -> 240 | O22: 7
A23: =A22 -> 46164 | B23: =IF(C23<>"", B22 + TIME(0, 30, 0),B22) -> 0.14583333 | C23: 40 | D23: 3.15 | E23: 3.18 | F23: 3.11 | G23: 3.06 | H23: =IFERROR(AVERAGE(D23:G23),"") -> 3.125 | J23: U2 | K23: =IF(J23="","",ROUND(H23,2)) -> 3.13 | L23: U8 | M23: =IFERROR(VLOOKUP(L23,$J$16:$K$405,2,FALSE),"") -> 4.08 | N23: =IFERROR(SMALL($C$16:$C$405,O23),"") -> 280 | O23: 8
A24: =A23 -> 46164 | B24: =IF(C24<>"", B23 + TIME(0, 30, 0),B23) -> 0.16666667 | C24: 0 | D24: 3.09 | E24: 3.11 | F24: 3.01 | G24: 2.94 | H24: =IFERROR(AVERAGE(D24:G24),"") -> 3.0375 | J24: U1 | K24: =IF(J24="","",ROUND(H24,2)) -> 3.04 | L24: U9 | M24: =IFERROR(VLOOKUP(L24,$J$16:$K$405,2,FALSE),"") -> 4.18 | N24: =IFERROR(SMALL($C$16:$C$405,O24),"") -> 300 | O24: 9
K25: =IF(J25="","",ROUND(H25,2)) | L25: U10 | M25: =IFERROR(VLOOKUP(L25,$J$16:$K$405,2,FALSE),"") | N25: =IFERROR(SMALL($C$16:$C$405,O25),"") | O25: 10
K26: =IF(J26="","",ROUND(H26,2)) | L26: U11 | M26: =IFERROR(VLOOKUP(L26,$J$16:$K$405,2,FALSE),"") | N26: =IFERROR(SMALL($C$16:$C$405,O26),"") | O26: 11
K27: =IF(J27="","",ROUND(H27,2)) | L27: U12 | M27: =IFERROR(VLOOKUP(L27,$J$16:$K$405,2,FALSE),"") | N27: =IFERROR(SMALL($C$16:$C$405,O27),"") | O27: 12
K28: =IF(J28="","",ROUND(H28,2)) | L28: U13 | M28: =IFERROR(VLOOKUP(L28,$J$16:$K$405,2,FALSE),"") | N28: =IFERROR(SMALL($C$16:$C$405,O28),"") | O28: 13
K29: =IF(J29="","",ROUND(H29,2)) | L29: U14 | M29: =IFERROR(VLOOKUP(L29,$J$16:$K$405,2,FALSE),"") | N29: =IFERROR(SMALL($C$16:$C$405,O29),"") | O29: 14
K30: =IF(J30="","",ROUND(H30,2)) | L30: U15 | M30: =IFERROR(VLOOKUP(L30,$J$16:$K$405,2,FALSE),"") | N30: =IFERROR(SMALL($C$16:$C$405,O30),"") | O30: 15
K31: =IF(J31="","",ROUND(H31,2)) | L31: U16 | M31: =IFERROR(VLOOKUP(L31,$J$16:$K$405,2,FALSE),"") | N31: =IFERROR(SMALL($C$16:$C$405,O31),"") | O31: 16
K32: =IF(J32="","",ROUND(H32,2)) | L32: U17 | M32: =IFERROR(VLOOKUP(L32,$J$16:$K$405,2,FALSE),"") | N32: =IFERROR(SMALL($C$16:$C$405,O32),"") | O32: 17
K33: =IF(J33="","",ROUND(H33,2)) | L33: U18 | M33: =IFERROR(VLOOKUP(L33,$J$16:$K$405,2,FALSE),"") | N33: =IFERROR(SMALL($C$16:$C$405,O33),"") | O33: 18
K34: =IF(J34="","",ROUND(H34,2)) | L34: U19 | M34: =IFERROR(VLOOKUP(L34,$J$16:$K$405,2,FALSE),"") | N34: =IFERROR(SMALL($C$16:$C$405,O34),"") | O34: 19
K35: =IF(J35="","",ROUND(H35,2)) | L35: U20 | M35: =IFERROR(VLOOKUP(L35,$J$16:$K$405,2,FALSE),"") | N35: =IFERROR(SMALL($C$16:$C$405,O35),"") | O35: 20
K36: =IF(J36="","",ROUND(H36,2)) | L36: U21 | M36: =IFERROR(VLOOKUP(L36,$J$16:$K$405,2,FALSE),"") | N36: =IFERROR(SMALL($C$16:$C$405,O36),"") | O36: 21
... K39: =IF(J39="","",ROUND(H39,2)) | L39: U24 | M39: =IFERROR(VLOOKUP(L39,$J$16:$K$405,2,FALSE),"") | N39: =IFERROR(SMALL($C$16:$C$405,O39),"") | O39: 24
H40: =IFERROR(AVERAGE(D40:G40),"") | K40: =IF(J40="","",ROUND(H40,2)) | L40: U25 | M40: =IFERROR(VLOOKUP(L40,$J$16:$K$405,2,FALSE),"") | N40: =IFERROR(SMALL($C$16:$C$405,O40),"") | O40: 25
H41: =IFERROR(AVERAGE(D41:G41),"") | K41: =IF(J41="","",ROUND(H41,2)) | L41: U26 | M41: =IFERROR(VLOOKUP(L41,$J$16:$K$405,2,FALSE),"") | N41: =IFERROR(SMALL($C$16:$C$405,O41),"") | O41: 26
H42: =IFERROR(AVERAGE(D42:G42),"") | K42: =IF(J42="","",ROUND(H42,2)) | L42: U27 | M42: =IFERROR(VLOOKUP(L42,$J$16:$K$405,2,FALSE),"") | N42: =IFERROR(SMALL($C$16:$C$405,O42),"") | O42: 27
H43: =IFERROR(AVERAGE(D43:G43),"") | K43: =IF(J43="","",ROUND(H43,2)) | L43: U28 | M43: =IFERROR(VLOOKUP(L43,$J$16:$K$405,2,FALSE),"") | N43: =IFERROR(SMALL($C$16:$C$405,O43),"") | O43: 28
H44: =IFERROR(AVERAGE(D44:G44),"") | K44: =IF(J44="","",ROUND(H44,2)) | L44: U29 | M44: =IFERROR(VLOOKUP(L44,$J$16:$K$405,2,FALSE),"") | N44: =IFERROR(SMALL($C$16:$C$405,O44),"") | O44: 29
H45: =IFERROR(AVERAGE(D45:G45),"") | K45: =IF(J45="","",ROUND(H45,2)) | L45: U30 | M45: =IFERROR(VLOOKUP(L45,$J$16:$K$405,2,FALSE),"") | N45: =IFERROR(SMALL($C$16:$C$405,O45),"") | O45: 30
H46: =IFERROR(AVERAGE(D46:G46),"") | K46: =IF(J46="","",ROUND(H46,2)) | L46: U31 | M46: =IFERROR(VLOOKUP(L46,$J$16:$K$405,2,FALSE),"") | N46: =IFERROR(SMALL($C$16:$C$405,O46),"") | O46: 31
H47: =IFERROR(AVERAGE(D47:G47),"") | K47: =IF(J47="","",ROUND(H47,2)) | L47: U32 | M47: =IFERROR(VLOOKUP(L47,$J$16:$K$405,2,FALSE),"") | N47: =IFERROR(SMALL($C$16:$C$405,O47),"") | O47: 32
...

Sheet F1
B3: NORTHEAST RESEARCH LABORATORY &
B4: TESTING PRIVATE LIMITED
B6: M/N : (+91) 9577782943, EMAIL : OFFICE@NERLT.COM
B7: Office: Room No.50, G.M.C. Market Complex, Chandmari, Guwahati-781003
B8: Lab: House No 4, Salbari- Noonmati Road, Noonmati, Guwahati, Assam 781020
AD10: X1 | AE10: Y1 | AF10: X2 | AG10: Y2
B11: =UPPER("2.05 : Fig 1 : load settlement graph from field data") -> 2.05 : FIG 1 : LOAD SETTLEMENT GRAPH FROM FIELD DATA | Y11: HZL | Z11: HZL | AA11: VER | AB11: VER | AD11: Loading Mean | AE11: Load value in Tonne | AF11: Unloading Mean | AG11: Load value in Tonne
Y14: X | Z14: Y | AA14: X | AB14: Y | AD14: Loading | AF14: Unloading
Y15: 0 | Z15: =AB16 -> 300 | AA15: =AA16 -> 4.18 | AB15: 0 | AD15: =IF(T1L!M16="","Delete",T1L!M16) -> 0 | AE15: =IF(T1L!N16="","Delete",T1L!N16) -> 0 | AF15: =IF(T1U!M16="","Delete",T1U!M16) -> 3.04 | AG15: =IF(T1U!N16="","Delete",T1U!N16) -> 0
Y16: =AA16 -> 4.18 | Z16: =AB16 -> 300 | AA16: =AA39 -> 4.18 | AB16: =AB39 -> 300 | AD16: =IF(T1L!M17="","Delete",T1L!M17) -> 0.47 | AE16: =IF(T1L!N17="","Delete",T1L!N17) -> 40 | AF16: =IF(T1U!M17="","Delete",T1U!M17) -> 3.13 | AG16: =IF(T1U!N17="","Delete",T1U!N17) -> 40
AD17: =IF(T1L!M18="","Delete",T1L!M18) -> 0.95 | AE17: =IF(T1L!N18="","Delete",T1L!N18) -> 80 | AF17: =IF(T1U!M18="","Delete",T1U!M18) -> 3.23 | AG17: =IF(T1U!N18="","Delete",T1U!N18) -> 80
AA18: mm | AB18: Tonne | AD18: =IF(T1L!M19="","Delete",T1L!M19) -> 1.37 | AE18: =IF(T1L!N19="","Delete",T1L!N19) -> 120 | AF18: =IF(T1U!M19="","Delete",T1U!M19) -> 3.4 | AG18: =IF(T1U!N19="","Delete",T1U!N19) -> 120
Y19: =AA40 -> 15 | Z19: =CONCATENATE("<",Y19) -> <15 | AA19: {=MAX(IF(AD15:AD63<Y19,AD15:AD63))} -> 4.18 | AB19: =VLOOKUP(AA19,AD15:AG63,2,FALSE) -> 300 | AD19: =IF(T1L!M20="","Delete",T1L!M20) -> 1.84 | AE19: =IF(T1L!N20="","Delete",T1L!N20) -> 160 | AF19: =IF(T1U!M20="","Delete",T1U!M20) -> 3.58 | AG19: =IF(T1U!N20="","Delete",T1U!N20) -> 160
Z20: =CONCATENATE(">",Y19) -> >15 | AA20: {=IFERROR(MIN(IF(AD15:AD63>Y19,AD15:AD63)),"")} -> 0 | AB20: =VLOOKUP(AA20,AD15:AG63,2,FALSE) -> 0 | AD20: =IF(T1L!M21="","Delete",T1L!M21) -> 2.2 | AE20: =IF(T1L!N21="","Delete",T1L!N21) -> 200 | AF20: =IF(T1U!M21="","Delete",T1U!M21) -> 3.77 | AG20: =IF(T1U!N21="","Delete",T1U!N21) -> 200
Z21: differ | AA21: =AA20-AA19 -> -4.18 | AB21: =AB20-AB19 -> -300 | AD21: =IF(T1L!M22="","Delete",T1L!M22) -> 2.93 | AE21: =IF(T1L!N22="","Delete",T1L!N22) -> 240 | AF21: =IF(T1U!M22="","Delete",T1U!M22) -> 3.95 | AG21: =IF(T1U!N22="","Delete",T1U!N22) -> 240
Z22: unit | AA22: 1 | AB22: =ROUND(AB21/AA21,2) -> 71.77 | AD22: =IF(T1L!M23="","Delete",T1L!M23) -> 3.43 | AE22: =IF(T1L!N23="","Delete",T1L!N23) -> 280 | AF22: =IF(T1U!M23="","Delete",T1U!M23) -> 4.08 | AG22: =IF(T1U!N23="","Delete",T1U!N23) -> 280
Z23: deduct | AA23: =AA20-Y19 -> -15 | AB23: =ROUND(AA23*AB22,2) -> -1076.55 | AD23: =IF(T1L!M24="","Delete",T1L!M24) -> 4.18 | AE23: =IF(T1L!N24="","Delete",T1L!N24) -> 300 | AF23: =IF(T1U!M24="","Delete",T1U!M24) -> 4.18 | AG23: =IF(T1U!N24="","Delete",T1U!N24) -> 300
Z24: result | AA24: =Y19 -> 15 | AB24: =AB20-AB23 -> 1076.55
Z28: dia | AA28: ='Th1'!AL38 -> 750 | AB28: mm
Z30: safe load | AA30: ='Th1'!AL44 -> 200 | AB30: tonne
Z31: Test Load | AA31: ='Th1'!AL45 -> 300 | AB31: tonne
Z32: 2% dia | AA32: =AA28*2% -> 15 | AB32: mm
Y33: C | Z33: 12 or 18 | AA33: =IF(AA28>600,18,12) -> 18 | AB33: mm
Z34: Min A,B | AA34: =SMALL(AA32:AA33,1) -> 15 | AB34: mm
Z35: Gross | AA35: =MAX(AD15:AD63) -> 4.18 | AB35: mm
B36: =UPPER("2.06 : ANALYSIS OF TEST RESULTS") -> 2.06 : ANALYSIS OF TEST RESULTS | Z36: Net settlement | AA36: =MIN(AF15:AF63) -> 3.04 | AB36: mm
Z37: Rebound | AA37: =AA35-AA36 -> 1.14 | AB37: mm
B38: =IF(AA28>600,CONCATENATE("1) Maximum settlement observed for pile dia ",AA28," mm is ",AA35," mm for test load is ",AA31," Tonne."),IF(AA28<=600,CONCATENATE("Maximum settlement observed for pile dia ",AA28," mm is ",AA35," mm for test load is ",AA31," Tonne."),"")) -> 1) Maximum settlement observed for pile dia 750 mm is 4.18 mm for test load is 300 Tonne. | Z38: % Rebound | AA38: =ROUND((AA35-AA36)/AA35*100,2) -> 27.27
B39: =IF(AA28<=600,"",IF(AA28>600,IF(AA35<AA34,CONCATENATE("2) 2% of pile diameter ",AA28," mm i.e. ",AA32," mm or ",AA33," mm Settlement is not achieved."),CONCATENATE("2) For 2% of pile diameter ",AA28," mm i.e. ",AA32," mm or ",AA33," mm, Lesser one i.e. ",AA34," mm is considered")))) -> 2) 2% of pile diameter 750 mm i.e. 15 mm or 18 mm Settlement is not achieved. | Y39: A | Z39: test | AA39: =AA35 -> 4.18 | AB39: =MAX(AE15:AE63) -> 300
B40: =IF(AA28>600,IF(AA39<AA41,CONCATENATE("Hence considering above two criteria as per para 2.02, Maximum Settlement is ",AA39," mm and Hence, Estimated Safe Load i.e. ",AA30," Tonne."),CONCATENATE("Maximum observed Settlement is more than ",AA41," mm. Therefore redesign with new estimated safe load lesser than the present one is required.")),IF(AA39>AA42,CONCATENATE("Maximum observed Settlement is more than ",AA42," mm. Therefore redesign with new estimated safe load lesser than the present one is required."),CONCATENATE("Maximum Settlement is ",AA39," mm which is lesser that ",AA42, " mm and Hence, Estimated Safe Load i.e. ",AA30," Tonne may be accepted for design."))) -> Hence considering above two criteria as per para 2.02, Maximum Settlement is 4.18 mm and Hence, Estimated Safe Load i.e. 200 Tonne. | Y40: B | Z40: interpol | AA40: =AA32 -> 15 | AB40: =AB24 -> 1076.55
B41: =CONCATENATE("Gross Settlement = ",AA35," mm") -> Gross Settlement = 4.18 mm | Z41: Min A,B | AA41: =AA34 -> 15 | AB41: mm
B42: =CONCATENATE("Net Settlement = ",AA36," mm") -> Net Settlement = 3.04 mm | Y42: C | Z42: 12 or 18 | AA42: =IF(AA28>600,18,12) -> 18 | AB42: =AB52 -> 1291.86
B43: =CONCATENATE("Rebound = ",AA37," mm") -> Rebound = 1.14 mm | Z43: Min A,B | AA43: =SMALL(AA39:AA40,1) -> 4.18 | AB43: =SMALL(AB39:AB40,1) -> 300
B44: =CONCATENATE("Percent of Rebound = ",AA38," %") -> Percent of Rebound = 27.27 %
AA46: mm | AB46: Tonne
Y47: =AA42 -> 18 | Z47: =CONCATENATE("<",Y47) -> <18 | AA47: {=MAX(IF(AD15:AD63<Y47,AD15:AD63))} -> 4.18 | AB47: =VLOOKUP(AA47,AD15:AG63,2,FALSE) -> 300
Z48: =CONCATENATE(">",Y47) -> >18 | AA48: {=IFERROR(MIN(IF(AD15:AD63>Y47,AD15:AD63)),"")} -> 0 | AB48: =VLOOKUP(AA48,AD15:AG63,2,FALSE) -> 0
Z49: differ | AA49: =AA48-AA47 -> -4.18 | AB49: =AB48-AB47 -> -300
Z50: unit | AA50: 1 | AB50: =ROUND(AB49/AA49,2) -> 71.77
Z51: deduct | AA51: =AA48-Y47 -> -18 | AB51: =ROUND(AA51*AB50,2) -> -1291.86
...

Sheet SitePhotoGraphs
A3: NORTHEAST RESEARCH LABORATORY &
A4: TESTING PRIVATE LIMITED
A6: M/N : (+91) 9577782943, EMAIL : OFFICE@NERLT.COM
A7: Office: Room No.50, G.M.C. Market Complex, Chandmari, Guwahati-781003
A8: Lab: House No 4, Salbari- Noonmati Road, Noonmati, Guwahati, Assam 781020
A11: 3. Site Photo Graphs
